[2025-05-12T20:45:25.475+0000] {local_task_job_runner.py:123} INFO - ::group::Pre task execution logs
[2025-05-12T20:45:25.541+0000] {taskinstance.py:2614} INFO - Dependencies all met for dep_context=non-requeueable deps ti=<TaskInstance: etl_csv_pipeline_v2.clean_data manual__2025-05-12T20:45:11.735907+00:00 [queued]>
[2025-05-12T20:45:25.572+0000] {taskinstance.py:2614} INFO - Dependencies all met for dep_context=requeueable deps ti=<TaskInstance: etl_csv_pipeline_v2.clean_data manual__2025-05-12T20:45:11.735907+00:00 [queued]>
[2025-05-12T20:45:25.578+0000] {taskinstance.py:2867} INFO - Starting attempt 1 of 1
[2025-05-12T20:45:25.622+0000] {taskinstance.py:2890} INFO - Executing <Task(PythonOperator): clean_data> on 2025-05-12 20:45:11.735907+00:00
[2025-05-12T20:45:25.644+0000] {warnings.py:112} WARNING - /home/***/.local/lib/python3.12/site-packages/***/task/task_runner/standard_task_runner.py:70: DeprecationWarning: This process (pid=86) is multi-threaded, use of fork() may lead to deadlocks in the child.
  pid = os.fork()

[2025-05-12T20:45:25.659+0000] {standard_task_runner.py:72} INFO - Started process 94 to run task
[2025-05-12T20:45:25.665+0000] {standard_task_runner.py:104} INFO - Running: ['***', 'tasks', 'run', 'etl_csv_pipeline_v2', 'clean_data', 'manual__2025-05-12T20:45:11.735907+00:00', '--job-id', '123', '--raw', '--subdir', 'DAGS_FOLDER/etl_pipeline.py', '--cfg-path', '/tmp/tmpvq0qhjrs']
[2025-05-12T20:45:25.679+0000] {standard_task_runner.py:105} INFO - Job 123: Subtask clean_data
[2025-05-12T20:45:25.911+0000] {task_command.py:467} INFO - Running <TaskInstance: etl_csv_pipeline_v2.clean_data manual__2025-05-12T20:45:11.735907+00:00 [running]> on host 88025fb06de6
[2025-05-12T20:45:26.226+0000] {taskinstance.py:3134} INFO - Exporting env vars: AIRFLOW_CTX_DAG_OWNER='***' AIRFLOW_CTX_DAG_ID='etl_csv_pipeline_v2' AIRFLOW_CTX_TASK_ID='clean_data' AIRFLOW_CTX_EXECUTION_DATE='2025-05-12T20:45:11.735907+00:00' AIRFLOW_CTX_TRY_NUMBER='1' AIRFLOW_CTX_DAG_RUN_ID='manual__2025-05-12T20:45:11.735907+00:00'
[2025-05-12T20:45:26.228+0000] {logging_mixin.py:190} INFO - Task instance is in running state
[2025-05-12T20:45:26.231+0000] {logging_mixin.py:190} INFO -  Previous state of the Task instance: queued
[2025-05-12T20:45:26.233+0000] {logging_mixin.py:190} INFO - Current task name:clean_data state:running start_date:2025-05-12 20:45:25.547670+00:00
[2025-05-12T20:45:26.235+0000] {logging_mixin.py:190} INFO - Dag name:etl_csv_pipeline_v2 and current dag run status:running
[2025-05-12T20:45:26.236+0000] {taskinstance.py:732} INFO - ::endgroup::
[2025-05-12T20:45:26.267+0000] {clean_data.py:43} INFO - üì• Leyendo archivo CSV: /tmp/superstore_raw.csv
[2025-05-12T20:45:31.648+0000] {cleaning_helpers.py:14} INFO - üßπ Eliminando columnas duplicadas: ['Sales']
[2025-05-12T20:45:31.661+0000] {cleaning_helpers.py:26} INFO - üóëÔ∏è Eliminando columnas: ['Transaction']
[2025-05-12T20:45:31.670+0000] {clean_data.py:53} INFO - üßº Limpiando columna: Sales
[2025-05-12T20:45:31.672+0000] {taskinstance.py:3313} ERROR - Task failed with exception
Traceback (most recent call last):
  File "/home/airflow/.local/lib/python3.12/site-packages/airflow/models/taskinstance.py", line 768, in _execute_task
    result = _execute_callable(context=context, **execute_callable_kwargs)
             ^^^^^^^^^^^^^^^^^^^^^^^^^^^^^^^^^^^^^^^^^^^^^^^^^^^^^^^^^^^^^
  File "/home/airflow/.local/lib/python3.12/site-packages/airflow/models/taskinstance.py", line 734, in _execute_callable
    return ExecutionCallableRunner(
           ^^^^^^^^^^^^^^^^^^^^^^^^
  File "/home/airflow/.local/lib/python3.12/site-packages/airflow/utils/operator_helpers.py", line 252, in run
    return self.func(*args, **kwargs)
           ^^^^^^^^^^^^^^^^^^^^^^^^^^
  File "/home/airflow/.local/lib/python3.12/site-packages/airflow/models/baseoperator.py", line 424, in wrapper
    return func(self, *args, **kwargs)
           ^^^^^^^^^^^^^^^^^^^^^^^^^^^
  File "/home/airflow/.local/lib/python3.12/site-packages/airflow/operators/python.py", line 238, in execute
    return_value = self.execute_callable()
                   ^^^^^^^^^^^^^^^^^^^^^^^
  File "/home/airflow/.local/lib/python3.12/site-packages/airflow/operators/python.py", line 256, in execute_callable
    return runner.run(*self.op_args, **self.op_kwargs)
           ^^^^^^^^^^^^^^^^^^^^^^^^^^^^^^^^^^^^^^^^^^^
  File "/home/airflow/.local/lib/python3.12/site-packages/airflow/utils/operator_helpers.py", line 252, in run
    return self.func(*args, **kwargs)
           ^^^^^^^^^^^^^^^^^^^^^^^^^^
  File "/opt/airflow/scripts/clean_data.py", line 54, in clean_data
    df = clean_column(df, column_name)
         ^^^^^^^^^^^^^^^^^^^^^^^^^^^^^
  File "/opt/airflow/scripts/clean_data.py", line 19, in clean_column
    raise ValueError(f"‚ùå La columna '{column_name}' no existe en el DataFrame")
ValueError: ‚ùå La columna 'Sales' no existe en el DataFrame
[2025-05-12T20:45:31.697+0000] {logging_mixin.py:190} INFO - Task instance in failure state
[2025-05-12T20:45:31.698+0000] {logging_mixin.py:190} INFO - Task start:2025-05-12 20:45:25.547670+00:00 end:2025-05-12 20:45:31.696749+00:00 duration:6.149079
[2025-05-12T20:45:31.699+0000] {logging_mixin.py:190} INFO - Task:<Task(PythonOperator): clean_data> dag:<DAG: etl_csv_pipeline_v2> dagrun:<DagRun etl_csv_pipeline_v2 @ 2025-05-12 20:45:11.735907+00:00: manual__2025-05-12T20:45:11.735907+00:00, state:running, queued_at: 2025-05-12 20:45:11.770364+00:00. externally triggered: True>
[2025-05-12T20:45:31.700+0000] {logging_mixin.py:190} INFO - Failure caused by ‚ùå La columna 'Sales' no existe en el DataFrame
[2025-05-12T20:45:31.702+0000] {taskinstance.py:1226} INFO - Marking task as FAILED. dag_id=etl_csv_pipeline_v2, task_id=clean_data, run_id=manual__2025-05-12T20:45:11.735907+00:00, execution_date=20250512T204511, start_date=20250512T204525, end_date=20250512T204531
[2025-05-12T20:45:31.781+0000] {taskinstance.py:341} INFO - ::group::Post task execution logs
[2025-05-12T20:45:31.783+0000] {standard_task_runner.py:124} ERROR - Failed to execute job 123 for task clean_data (‚ùå La columna 'Sales' no existe en el DataFrame; 94)
Traceback (most recent call last):
  File "/home/airflow/.local/lib/python3.12/site-packages/airflow/task/task_runner/standard_task_runner.py", line 117, in _start_by_fork
    ret = args.func(args, dag=self.dag)
          ^^^^^^^^^^^^^^^^^^^^^^^^^^^^^
  File "/home/airflow/.local/lib/python3.12/site-packages/airflow/cli/cli_config.py", line 49, in command
    return func(*args, **kwargs)
           ^^^^^^^^^^^^^^^^^^^^^
  File "/home/airflow/.local/lib/python3.12/site-packages/airflow/utils/cli.py", line 116, in wrapper
    return f(*args, **kwargs)
           ^^^^^^^^^^^^^^^^^^
  File "/home/airflow/.local/lib/python3.12/site-packages/airflow/cli/commands/task_command.py", line 483, in task_run
    task_return_code = _run_task_by_selected_method(args, _dag, ti)
                       ^^^^^^^^^^^^^^^^^^^^^^^^^^^^^^^^^^^^^^^^^^^^
  File "/home/airflow/.local/lib/python3.12/site-packages/airflow/cli/commands/task_command.py", line 256, in _run_task_by_selected_method
    return _run_raw_task(args, ti)
           ^^^^^^^^^^^^^^^^^^^^^^^
  File "/home/airflow/.local/lib/python3.12/site-packages/airflow/cli/commands/task_command.py", line 341, in _run_raw_task
    return ti._run_raw_task(
           ^^^^^^^^^^^^^^^^^
  File "/home/airflow/.local/lib/python3.12/site-packages/airflow/utils/session.py", line 97, in wrapper
    return func(*args, session=session, **kwargs)
           ^^^^^^^^^^^^^^^^^^^^^^^^^^^^^^^^^^^^^^
  File "/home/airflow/.local/lib/python3.12/site-packages/airflow/models/taskinstance.py", line 3006, in _run_raw_task
    return _run_raw_task(
           ^^^^^^^^^^^^^^
  File "/home/airflow/.local/lib/python3.12/site-packages/airflow/models/taskinstance.py", line 274, in _run_raw_task
    TaskInstance._execute_task_with_callbacks(
  File "/home/airflow/.local/lib/python3.12/site-packages/airflow/models/taskinstance.py", line 3161, in _execute_task_with_callbacks
    result = self._execute_task(context, task_orig)
             ^^^^^^^^^^^^^^^^^^^^^^^^^^^^^^^^^^^^^^
  File "/home/airflow/.local/lib/python3.12/site-packages/airflow/models/taskinstance.py", line 3185, in _execute_task
    return _execute_task(self, context, task_orig)
           ^^^^^^^^^^^^^^^^^^^^^^^^^^^^^^^^^^^^^^^
  File "/home/airflow/.local/lib/python3.12/site-packages/airflow/models/taskinstance.py", line 768, in _execute_task
    result = _execute_callable(context=context, **execute_callable_kwargs)
             ^^^^^^^^^^^^^^^^^^^^^^^^^^^^^^^^^^^^^^^^^^^^^^^^^^^^^^^^^^^^^
  File "/home/airflow/.local/lib/python3.12/site-packages/airflow/models/taskinstance.py", line 734, in _execute_callable
    return ExecutionCallableRunner(
           ^^^^^^^^^^^^^^^^^^^^^^^^
  File "/home/airflow/.local/lib/python3.12/site-packages/airflow/utils/operator_helpers.py", line 252, in run
    return self.func(*args, **kwargs)
           ^^^^^^^^^^^^^^^^^^^^^^^^^^
  File "/home/airflow/.local/lib/python3.12/site-packages/airflow/models/baseoperator.py", line 424, in wrapper
    return func(self, *args, **kwargs)
           ^^^^^^^^^^^^^^^^^^^^^^^^^^^
  File "/home/airflow/.local/lib/python3.12/site-packages/airflow/operators/python.py", line 238, in execute
    return_value = self.execute_callable()
                   ^^^^^^^^^^^^^^^^^^^^^^^
  File "/home/airflow/.local/lib/python3.12/site-packages/airflow/operators/python.py", line 256, in execute_callable
    return runner.run(*self.op_args, **self.op_kwargs)
           ^^^^^^^^^^^^^^^^^^^^^^^^^^^^^^^^^^^^^^^^^^^
  File "/home/airflow/.local/lib/python3.12/site-packages/airflow/utils/operator_helpers.py", line 252, in run
    return self.func(*args, **kwargs)
           ^^^^^^^^^^^^^^^^^^^^^^^^^^
  File "/opt/airflow/scripts/clean_data.py", line 54, in clean_data
    df = clean_column(df, column_name)
         ^^^^^^^^^^^^^^^^^^^^^^^^^^^^^
  File "/opt/airflow/scripts/clean_data.py", line 19, in clean_column
    raise ValueError(f"‚ùå La columna '{column_name}' no existe en el DataFrame")
ValueError: ‚ùå La columna 'Sales' no existe en el DataFrame
[2025-05-12T20:45:31.892+0000] {local_task_job_runner.py:266} INFO - Task exited with return code 1
[2025-05-12T20:45:31.972+0000] {taskinstance.py:3901} INFO - 0 downstream tasks scheduled from follow-on schedule check
[2025-05-12T20:45:31.997+0000] {local_task_job_runner.py:245} INFO - ::endgroup::
